srun: /usr/lib64/slurm/select_alps.so: Incompatible Slurm plugin version (18.08.6)
srun: error: Couldn't load specified plugin name for select/alps: Incompatible plugin version
srun: /usr/lib64/slurm/select_cray.so: Incompatible Slurm plugin version (18.08.6)
srun: error: Couldn't load specified plugin name for select/cray: Incompatible plugin version
srun: /usr/lib64/slurm/select_serial.so: Incompatible Slurm plugin version (18.08.6)
srun: error: Couldn't load specified plugin name for select/serial: Incompatible plugin version
srun: /usr/lib64/slurm/switch_cray.so: Incompatible Slurm plugin version (18.08.6)
srun: error: Couldn't load specified plugin name for switch/cray: Incompatible plugin version
2023-10-29 13:58:03.931078: I tensorflow/stream_executor/platform/default/dso_loader.cc:49] Successfully opened dynamic library libcudart.so.10.1
INFO flwr 2023-10-29 13:58:09,716 | grpc.py:49 | Opened insecure gRPC connection (no certificates were passed)
DEBUG flwr 2023-10-29 13:58:09,719 | connection.py:42 | ChannelConnectivity.IDLE
DEBUG flwr 2023-10-29 13:58:09,720 | connection.py:42 | ChannelConnectivity.READY
DEBUG flwr 2023-10-29 13:58:10,218 | connection.py:42 | ChannelConnectivity.IDLE
DEBUG flwr 2023-10-29 13:58:10,425 | connection.py:139 | gRPC channel closed
Traceback (most recent call last):
  File "client_10.py", line 49, in <module>
    main()
  File "client_10.py", line 44, in main
    fl.client.start_numpy_client(server_address="10.30.0.254:9000",
  File "/home/s124m21/.local/lib/python3.8/site-packages/flwr/client/app.py", line 288, in start_numpy_client
    start_client(
  File "/home/s124m21/.local/lib/python3.8/site-packages/flwr/client/app.py", line 201, in start_client
    task_ins = receive()
  File "/home/s124m21/.local/lib/python3.8/site-packages/flwr/client/grpc_client/connection.py", line 116, in receive
    server_message = next(server_message_iterator)
  File "/opt/miniconda3/lib/python3.8/site-packages/grpc/_channel.py", line 475, in __next__
    return self._next()
  File "/opt/miniconda3/lib/python3.8/site-packages/grpc/_channel.py", line 881, in _next
    raise self
grpc._channel._MultiThreadedRendezvous: <_MultiThreadedRendezvous of RPC that terminated with:
	status = StatusCode.UNAVAILABLE
	details = "Socket closed"
	debug_error_string = "UNKNOWN:Error received from peer  {grpc_message:"Socket closed", grpc_status:14, created_time:"2023-10-29T13:58:10.216112345+01:00"}"
>
srun: error: n04: task 0: Exited with exit code 1
