2023-10-29 14:12:44.235074: I tensorflow/stream_executor/platform/default/dso_loader.cc:49] Successfully opened dynamic library libcudart.so.10.1
INFO flwr 2023-10-29 14:12:50,412 | grpc.py:49 | Opened insecure gRPC connection (no certificates were passed)
DEBUG flwr 2023-10-29 14:12:50,415 | connection.py:42 | ChannelConnectivity.IDLE
DEBUG flwr 2023-10-29 14:12:50,416 | connection.py:42 | ChannelConnectivity.CONNECTING
DEBUG flwr 2023-10-29 14:12:53,559 | connection.py:42 | ChannelConnectivity.TRANSIENT_FAILURE
DEBUG flwr 2023-10-29 14:12:53,762 | connection.py:139 | gRPC channel closed
Traceback (most recent call last):
  File "client_3.py", line 49, in <module>
    main()
  File "client_3.py", line 44, in main
    fl.client.start_numpy_client(server_address="10.30.0.254:9000",
  File "/home/s124m21/.local/lib/python3.8/site-packages/flwr/client/app.py", line 288, in start_numpy_client
    start_client(
  File "/home/s124m21/.local/lib/python3.8/site-packages/flwr/client/app.py", line 201, in start_client
    task_ins = receive()
  File "/home/s124m21/.local/lib/python3.8/site-packages/flwr/client/grpc_client/connection.py", line 116, in receive
    server_message = next(server_message_iterator)
  File "/opt/miniconda3/lib/python3.8/site-packages/grpc/_channel.py", line 475, in __next__
    return self._next()
  File "/opt/miniconda3/lib/python3.8/site-packages/grpc/_channel.py", line 881, in _next
    raise self
grpc._channel._MultiThreadedRendezvous: <_MultiThreadedRendezvous of RPC that terminated with:
	status = StatusCode.UNAVAILABLE
	details = "failed to connect to all addresses; last error: UNAVAILABLE: ipv4:10.30.0.254:9000: recvmsg:Connection reset by peer"
	debug_error_string = "UNKNOWN:failed to connect to all addresses; last error: UNAVAILABLE: ipv4:10.30.0.254:9000: recvmsg:Connection reset by peer {grpc_status:14, created_time:"2023-10-29T14:12:53.557841075+01:00"}"
>
srun: error: n01: task 0: Exited with exit code 1
