2023-07-12 21:32:06.489090: I tensorflow/stream_executor/platform/default/dso_loader.cc:49] Successfully opened dynamic library libcudart.so.10.1
INFO flwr 2023-07-12 21:32:12,598 | grpc.py:50 | Opened insecure gRPC connection (no certificates were passed)
DEBUG flwr 2023-07-12 21:32:12,601 | connection.py:39 | ChannelConnectivity.IDLE
DEBUG flwr 2023-07-12 21:32:12,602 | connection.py:39 | ChannelConnectivity.READY
DEBUG flwr 2023-07-13 01:50:38,539 | connection.py:39 | ChannelConnectivity.IDLE
DEBUG flwr 2023-07-13 01:51:13,916 | connection.py:113 | gRPC channel closed
Traceback (most recent call last):
  File "client_5.py", line 232, in <module>
    main()
  File "client_5.py", line 227, in main
    fl.client.start_numpy_client(server_address="10.30.0.254:9000",
  File "/home/s124m21/.local/lib/python3.8/site-packages/flwr/client/app.py", line 252, in start_numpy_client
    start_client(
  File "/home/s124m21/.local/lib/python3.8/site-packages/flwr/client/app.py", line 174, in start_client
    server_message = receive()
  File "/home/s124m21/.local/lib/python3.8/site-packages/flwr/client/grpc_client/connection.py", line 105, in <lambda>
    receive: Callable[[], ServerMessage] = lambda: next(server_message_iterator)
  File "/opt/miniconda3/lib/python3.8/site-packages/grpc/_channel.py", line 475, in __next__
    return self._next()
  File "/opt/miniconda3/lib/python3.8/site-packages/grpc/_channel.py", line 864, in _next
    raise self
grpc._channel._MultiThreadedRendezvous: <_MultiThreadedRendezvous of RPC that terminated with:
	status = StatusCode.UNAVAILABLE
	details = "Socket closed"
	debug_error_string = "UNKNOWN:Error received from peer ipv4:10.30.0.254:9000 {created_time:"2023-07-13T01:50:38.538908544+02:00", grpc_status:14, grpc_message:"Socket closed"}"
>
srun: error: n02: task 0: Exited with exit code 1
