srun: /usr/lib64/slurm/select_alps.so: Incompatible Slurm plugin version (18.08.6)
srun: error: Couldn't load specified plugin name for select/alps: Incompatible plugin version
srun: /usr/lib64/slurm/select_cray.so: Incompatible Slurm plugin version (18.08.6)
srun: error: Couldn't load specified plugin name for select/cray: Incompatible plugin version
srun: /usr/lib64/slurm/select_serial.so: Incompatible Slurm plugin version (18.08.6)
srun: error: Couldn't load specified plugin name for select/serial: Incompatible plugin version
srun: /usr/lib64/slurm/switch_cray.so: Incompatible Slurm plugin version (18.08.6)
srun: error: Couldn't load specified plugin name for switch/cray: Incompatible plugin version
2023-07-10 17:04:07.039279: I tensorflow/stream_executor/platform/default/dso_loader.cc:49] Successfully opened dynamic library libcudart.so.10.1
INFO flwr 2023-07-10 17:04:11,878 | grpc.py:50 | Opened insecure gRPC connection (no certificates were passed)
DEBUG flwr 2023-07-10 17:04:11,887 | connection.py:39 | ChannelConnectivity.IDLE
DEBUG flwr 2023-07-10 17:04:11,888 | connection.py:39 | ChannelConnectivity.CONNECTING
DEBUG flwr 2023-07-10 17:04:31,890 | connection.py:39 | ChannelConnectivity.TRANSIENT_FAILURE
DEBUG flwr 2023-07-10 17:04:32,093 | connection.py:113 | gRPC channel closed
Traceback (most recent call last):
  File "client_2.py", line 230, in <module>
    main()
  File "client_2.py", line 225, in main
    fl.client.start_numpy_client(server_address="10.30.0.254:9000",
  File "/home/s124m21/.local/lib/python3.8/site-packages/flwr/client/app.py", line 252, in start_numpy_client
    start_client(
  File "/home/s124m21/.local/lib/python3.8/site-packages/flwr/client/app.py", line 174, in start_client
    server_message = receive()
  File "/home/s124m21/.local/lib/python3.8/site-packages/flwr/client/grpc_client/connection.py", line 105, in <lambda>
    receive: Callable[[], ServerMessage] = lambda: next(server_message_iterator)
  File "/opt/miniconda3/lib/python3.8/site-packages/grpc/_channel.py", line 475, in __next__
    return self._next()
  File "/opt/miniconda3/lib/python3.8/site-packages/grpc/_channel.py", line 881, in _next
    raise self
grpc._channel._MultiThreadedRendezvous: <_MultiThreadedRendezvous of RPC that terminated with:
	status = StatusCode.UNAVAILABLE
	details = "failed to connect to all addresses; last error: UNKNOWN: ipv4:10.30.0.254:9000: connection attempt timed out before receiving SETTINGS frame"
	debug_error_string = "UNKNOWN:failed to connect to all addresses; last error: UNKNOWN: ipv4:10.30.0.254:9000: connection attempt timed out before receiving SETTINGS frame {grpc_status:14, created_time:"2023-07-10T17:04:31.889776645+02:00"}"
>
srun: error: n04: task 0: Exited with exit code 1
