2023-07-10 11:39:58.336911: I tensorflow/stream_executor/platform/default/dso_loader.cc:49] Successfully opened dynamic library libcudart.so.10.1
INFO flwr 2023-07-10 11:40:03,148 | grpc.py:50 | Opened insecure gRPC connection (no certificates were passed)
DEBUG flwr 2023-07-10 11:40:03,150 | connection.py:39 | ChannelConnectivity.IDLE
DEBUG flwr 2023-07-10 11:40:03,154 | connection.py:39 | ChannelConnectivity.CONNECTING
DEBUG flwr 2023-07-10 11:40:03,158 | connection.py:113 | gRPC channel closed
Exception in thread Thread-1:
Traceback (most recent call last):
  File "/opt/miniconda3/lib/python3.8/threading.py", line 932, in _bootstrap_inner
Traceback (most recent call last):
  File "client_1.py", line 216, in <module>
    main()
  File "client_1.py", line 211, in main
    self.run()
  File "/opt/miniconda3/lib/python3.8/threading.py", line 870, in run
    fl.client.start_numpy_client(server_address="10.30.0.254:9000",
  File "/home/s124m21/.local/lib/python3.8/site-packages/flwr/client/app.py", line 252, in start_numpy_client
    start_client(
  File "/home/s124m21/.local/lib/python3.8/site-packages/flwr/client/app.py", line 174, in start_client
    self._target(*self._args, **self._kwargs)
  File "src/python/grpcio/grpc/_cython/_cygrpc/thread.pyx.pxi", line 53, in grpc._cython.cygrpc._run_with_context._run
    server_message = receive()
  File "/home/s124m21/.local/lib/python3.8/site-packages/flwr/client/grpc_client/connection.py", line 105, in <lambda>
    receive: Callable[[], ServerMessage] = lambda: next(server_message_iterator)
  File "/opt/miniconda3/lib/python3.8/site-packages/grpc/_channel.py", line 475, in __next__
    return self._next()
  File "/opt/miniconda3/lib/python3.8/site-packages/grpc/_channel.py", line 881, in _next
    raise self
grpc._channel._MultiThreadedRendezvous: <_MultiThreadedRendezvous of RPC that terminated with:
	status = StatusCode.UNAVAILABLE
	details = "failed to connect to all addresses; last error: UNKNOWN: ipv4:10.30.0.254:9000: Failed to connect to remote host: Connection refused"
	debug_error_string = "UNKNOWN:failed to connect to all addresses; last error: UNKNOWN: ipv4:10.30.0.254:9000: Failed to connect to remote host: Connection refused {created_time:"2023-07-10T11:40:03.155284835+02:00", grpc_status:14}"
>
  File "/opt/miniconda3/lib/python3.8/site-packages/grpc/_channel.py", line 1547, in _poll_connectivity
    event = channel.watch_connectivity_state(connectivity,
  File "src/python/grpcio/grpc/_cython/_cygrpc/channel.pyx.pxi", line 510, in grpc._cython.cygrpc.Channel.watch_connectivity_state
  File "src/python/grpcio/grpc/_cython/_cygrpc/channel.pyx.pxi", line 377, in grpc._cython.cygrpc._watch_connectivity_state
  File "src/python/grpcio/grpc/_cython/_cygrpc/channel.pyx.pxi", line 385, in grpc._cython.cygrpc._watch_connectivity_state
ValueError: Cannot monitor channel state: Channel closed!
srun: error: n02: task 0: Exited with exit code 1
