2023-08-22 21:55:28.605603: I tensorflow/stream_executor/platform/default/dso_loader.cc:49] Successfully opened dynamic library libcudart.so.10.1
INFO flwr 2023-08-22 21:55:35,786 | grpc.py:50 | Opened insecure gRPC connection (no certificates were passed)
DEBUG flwr 2023-08-22 21:55:35,825 | connection.py:39 | ChannelConnectivity.IDLE
DEBUG flwr 2023-08-22 21:55:35,826 | connection.py:39 | ChannelConnectivity.READY
DEBUG flwr 2023-08-22 21:55:57,217 | connection.py:39 | ChannelConnectivity.IDLE
DEBUG flwr 2023-08-22 21:55:57,423 | connection.py:113 | gRPC channel closed
Traceback (most recent call last):
  File "client_1.py", line 153, in <module>
    main()
  File "client_1.py", line 147, in main
    fl.client.start_numpy_client(server_address="10.30.0.254:9000",
  File "/home/s124m21/.local/lib/python3.8/site-packages/flwr/client/app.py", line 252, in start_numpy_client
    start_client(
  File "/home/s124m21/.local/lib/python3.8/site-packages/flwr/client/app.py", line 174, in start_client
    server_message = receive()
  File "/home/s124m21/.local/lib/python3.8/site-packages/flwr/client/grpc_client/connection.py", line 105, in <lambda>
    receive: Callable[[], ServerMessage] = lambda: next(server_message_iterator)
  File "/opt/miniconda3/lib/python3.8/site-packages/grpc/_channel.py", line 475, in __next__
    return self._next()
  File "/opt/miniconda3/lib/python3.8/site-packages/grpc/_channel.py", line 881, in _next
    raise self
grpc._channel._MultiThreadedRendezvous: <_MultiThreadedRendezvous of RPC that terminated with:
	status = StatusCode.UNAVAILABLE
	details = "Socket closed"
	debug_error_string = "UNKNOWN:Error received from peer  {grpc_message:"Socket closed", grpc_status:14, created_time:"2023-08-22T21:55:57.215759903+02:00"}"
>
srun: error: n17: task 0: Exited with exit code 1
